Workbook

Sheet サマリー（入力禁止）
B1: 2025年度 売上予算（見込み）
D2: 7～9月 | E2: 10～12月 | G2: 1～3月 | H2: 4～6月 | J2: 単位：千円 | M2: 単位：千円 | N2: (目標：5%) | R2: 月平均 | S2: 単位：人 | AF2: 平均要員数 | AI2: 要員増減 | AJ2: 1人当たりの売上
B3: 部門名 | D3: １Q | E3: ２Q | F3: 期計 | G3: ３Q | H3: ４Q | I3: 期計 | J3: 合計 | L3: 2024売上 | M3: 伸長額 | N3: 伸長率 | R3: 2022要員 | S3: 計画要員 | T3: 差異 | U3: 増減率 | V3: 2023年延べ人数 | W3: 2024年延べ人数 | X3: 2025年延べ人数（見込み） | Y3: 新人 | Z3: 努力目標 | AA3: 新人 | AF3: 2024年度 | AG3: 2025年度 | AI3: 係数 | AJ3: 2024年度 | AK3: 2025年度 | AL3: 伸長率
B4: 第一システムグループ(サポート) | C4: 作成請負 | D4: =第一!E11 -> 0 | E4: =第一!F11 -> 0 | F4: =SUM(D4:E4) -> 0 | G4: =第一!H11 -> 0 | H4: =第一!I11 -> 0 | I4: =SUM(G4:H4) -> 0 | J4: =SUM(F4,I4) -> 0 | AG4: 新人含む
C5: 作業請負 | D5: =第一!E17 -> 0 | E5: =第一!F17 -> 0 | F5: =SUM(D5:E5) -> 0 | G5: =第一!H17 -> 0 | H5: =第一!I17 -> 0 | I5: =SUM(G5:H5) -> 0 | J5: =SUM(F5,I5) -> 0
C6: 派遣 | D6: =第一!E28 -> 33400 | E6: =第一!F28 -> 33300 | F6: =SUM(D6:E6) -> 66700 | G6: =第一!H28 -> 33300 | H6: =第一!I28 -> 35000 | I6: =SUM(G6:H6) -> 68300 | J6: =SUM(F6,I6) -> 135000
C7: サービス | D7: =第一!E34 -> 0 | E7: =第一!F34 -> 0 | F7: =SUM(D7:E7) -> 0 | G7: =第一!H34 -> 0 | H7: =第一!I34 -> 0 | I7: =SUM(G7:H7) -> 0 | J7: =SUM(F7,I7) -> 0
C8: 計 | D8: =SUM(D4:D7) -> 33400 | E8: =SUM(E4:E7) -> 33300 | F8: =SUM(F4:F7) -> 66700 | G8: =SUM(G4:G7) -> 33300 | H8: =SUM(H4:H7) -> 35000 | I8: =SUM(I4:I7) -> 68300 | J8: =SUM(J4:J7) -> 135000 | L8: =155275-27049 -> 128226 | M8: =J8-L8 -> 6774 | N8: =(J8/L8)-1 -> 0.0528286 | R8: =357/12 -> 29.75 | S8: =第一!K38 -> 20.5 | T8: =S8-R8 -> -9.25 | U8: =(S8/R8)-1 -> -0.31092437 | V8: 309 | W8: 252 | X8: 240 | Z8: 319 | AA8: 15 | AC8: =310 -> 310 | AD8: 24 | AF8: =SUM(W8)/12 -> 21 | AG8: =SUM(X8:Y8)/12 -> 20 | AH8: サポート | AI8: =AG8/AF8 -> 0.95238095 | AJ8: =L8/AF8 -> 6106 | AK8: =J8/AG8 -> 6750 | AL8: =AK8/AJ8 -> 1.10547 | AM8: OK
B9: 第一システムグループ(開発) | C9: 作成請負 | D9: =第一開発!E12 -> 6500 | E9: =第一開発!F12 -> 7600 | F9: =第一開発!G12 -> 14100 | G9: =第一開発!H12 -> 7200 | H9: =第一開発!I12 -> 7200 | I9: =第一開発!J12 -> 14400 | J9: =第一開発!K12 -> 28500
C10: 作業請負 | D10: =第一開発!E18 -> 0 | E10: =第一開発!F18 -> 0 | F10: =第一開発!G18 -> 0 | G10: =第一開発!H18 -> 0 | H10: =第一開発!I18 -> 0 | I10: =第一開発!J18 -> 0 | J10: =第一開発!K18 -> 0
C11: 派遣 | D11: =第一開発!E28 -> 0 | E11: =第一開発!F28 -> 0 | F11: =第一開発!G28 -> 0 | G11: =第一開発!H28 -> 0 | H11: =第一開発!I28 -> 0 | I11: =第一開発!J28 -> 0 | J11: =第一開発!K28 -> 0
C12: サービス | D12: =第一開発!E34 -> 0 | E12: =第一開発!F34 -> 0 | F12: =第一開発!G34 -> 0 | G12: =第一開発!H34 -> 0 | H12: =第一開発!I34 -> 0 | I12: =第一開発!J34 -> 0 | J12: =第一開発!K34 -> 0
C13: 計 | D13: =SUM(D9:D12) -> 6500 | E13: =SUM(E9:E12) -> 7600 | F13: =SUM(F9:F12) -> 14100 | G13: =SUM(G9:G12) -> 7200 | H13: =SUM(H9:H12) -> 7200 | I13: =SUM(I9:I12) -> 14400 | J13: =SUM(J9:J12) -> 28500 | L13: 27049 | M13: =J13-L13 -> 1451 | N13: =(J13/L13)-1 -> 0.053643388 | W13: 69 | X13: 48 | Y13: 12 | AF13: =SUM(W13)/12 -> 5.75 | AG13: =SUM(X13:Y13)/12 -> 5 | AH13: 開発 | AI13: =AG13/AF13 -> 0.86956522 | AJ13: =L13/AF13 -> 4704.1739 | AK13: =J13/AG13 -> 5700 | AL13: =AK13/AJ13 -> 1.2116899 | AM13: 厳しいかな・・・
B14: 第二システムグループ | C14: 作成請負 | D14: =第ニ!E10 -> 21500 | E14: =第ニ!F10 -> 21500 | F14: =第ニ!G10 -> 43000 | G14: =第ニ!H10 -> 21500 | H14: =第ニ!I10 -> 21500 | I14: =第ニ!J10 -> 43000 | J14: =第ニ!K10 -> 86000
C15: 作業請負 | D15: =第ニ!E16 -> 0 | E15: =第ニ!F16 -> 0 | F15: =第ニ!G16 -> 0 | G15: =第ニ!H16 -> 0 | H15: =第ニ!I16 -> 0 | I15: =第ニ!J16 -> 0 | J15: =第ニ!K16 -> 0
C16: 派遣 | D16: =第ニ!E22 -> 0 | E16: =第ニ!F22 -> 0 | F16: =第ニ!G22 -> 0 | G16: =第ニ!H22 -> 0 | H16: =第ニ!I22 -> 0 | I16: =第ニ!J22 -> 0 | J16: =第ニ!K22 -> 0 | O16: ［補足］
C17: サービス | D17: =第ニ!E28 -> 0 | E17: =第ニ!F28 -> 0 | F17: =第ニ!G28 -> 0 | G17: =第ニ!H28 -> 0 | H17: =第ニ!I28 -> 0 | I17: =第ニ!J28 -> 0 | J17: =第ニ!K28 -> 0 | P17: 第二 CO含む
C18: 計 | D18: =SUM(D14:D17) -> 21500 | E18: =SUM(E14:E17) -> 21500 | F18: =SUM(F14:F17) -> 43000 | G18: =SUM(G14:G17) -> 21500 | H18: =SUM(H14:H17) -> 21500 | I18: =SUM(I14:I17) -> 43000 | J18: =SUM(J14:J17) -> 86000 | L18: 81600 | M18: =J18-L18 -> 4400 | N18: =(J18/L18)-1 -> 0.053921569 | P18: =SUM(J18,J23)-SUM(L18,L23) -> 4810 | Q18: =SUM(J18,J23)/SUM(L18,L23)-1 -> 0.049490688 | R18: =134/12 -> 11.166667 | S18: =第ニ!K32 -> 11 | T18: =S18-R18 -> -0.16666667 | U18: =(S18/R18)-1 -> -0.014925373 | V18: 132 | W18: 132 | X18: 132 | Y18: 0 | AC18: 132 | AF18: =SUM(W18)/12 -> 11 | AG18: =SUM(X18:Y18)/12 -> 11 | AH18: 第二 | AI18: =AG18/AF18 -> 1 | AJ18: =L18/AF18 -> 7418.1818 | AK18: =J18/AG18 -> 7818.1818 | AL18: =AK18/AJ18 -> 1.0539216 | AM18: OK
B19: 第二システムグループ(COネット） | C19: 作成請負 | D19: ='第ニ (CO)'!E10 -> 4000 | E19: ='第ニ (CO)'!F10 -> 4000 | F19: ='第ニ (CO)'!G10 -> 8000 | G19: ='第ニ (CO)'!H10 -> 4000 | H19: ='第ニ (CO)'!I10 -> 4000 | I19: ='第ニ (CO)'!J10 -> 8000 | J19: ='第ニ (CO)'!K10 -> 16000
C20: 作業請負 | D20: ='第ニ (CO)'!E16 -> 0 | E20: ='第ニ (CO)'!F16 -> 0 | F20: ='第ニ (CO)'!G16 -> 0 | G20: ='第ニ (CO)'!H16 -> 0 | H20: ='第ニ (CO)'!I16 -> 0 | I20: ='第ニ (CO)'!J16 -> 0 | J20: ='第ニ (CO)'!K16 -> 0
C21: 派遣 | D21: ='第ニ (CO)'!E22 -> 0 | E21: ='第ニ (CO)'!F22 -> 0 | F21: ='第ニ (CO)'!G22 -> 0 | G21: ='第ニ (CO)'!H22 -> 0 | H21: ='第ニ (CO)'!I22 -> 0 | I21: ='第ニ (CO)'!J22 -> 0 | J21: ='第ニ (CO)'!K22 -> 0
C22: サービス | D22: ='第ニ (CO)'!E28 -> 0 | E22: ='第ニ (CO)'!F28 -> 0 | F22: ='第ニ (CO)'!G28 -> 0 | G22: ='第ニ (CO)'!H28 -> 0 | H22: ='第ニ (CO)'!I28 -> 0 | I22: ='第ニ (CO)'!J28 -> 0 | J22: ='第ニ (CO)'!K28 -> 0
C23: 計 | D23: =SUM(D19:D22) -> 4000 | E23: =SUM(E19:E22) -> 4000 | F23: =SUM(F19:F22) -> 8000 | G23: =SUM(G19:G22) -> 4000 | H23: =SUM(H19:H22) -> 4000 | I23: =SUM(I19:I22) -> 8000 | J23: =SUM(J19:J22) -> 16000 | L23: 15590 | M23: =J23-L23 -> 410 | N23: =(J23/L23)-1 -> 0.02629891 | R23: =41/12 -> 3.4166667 | S23: ='第ニ (CO)'!K32 -> 2 | T23: =S23-R23 -> -1.4166667 | U23: =(S23/R23)-1 -> -0.41463415 | V23: 24 | X23: 24 | Y23: 0 | AC23: 24 | AF23: =SUM(W23)/12 -> 0 | AG23: =SUM(X23:Y23)/12 -> 2 | AH23: CO
B24: アプリ開発グループ | C24: 作成請負 | D24: =アプ開発!E10 -> 0 | E24: =アプ開発!F10 -> 0 | F24: =アプ開発!G10 -> 0 | G24: =アプ開発!H10 -> 0 | H24: =アプ開発!I10 -> 0 | I24: =アプ開発!J10 -> 0 | J24: =アプ開発!K10 -> 0
C25: 作業請負 | D25: =アプ開発!E17 -> 19366 | E25: =アプ開発!F17 -> 17024 | F25: =アプ開発!G17 -> 36390 | G25: =アプ開発!H17 -> 16562 | H25: =アプ開発!I17 -> 18937 | I25: =アプ開発!J17 -> 35499 | J25: =アプ開発!K17 -> 71889
C26: 派遣 | D26: =アプ開発!E23 -> 0 | E26: =アプ開発!F23 -> 0 | F26: =アプ開発!G23 -> 0 | G26: =アプ開発!H23 -> 0 | H26: =アプ開発!I23 -> 0 | I26: =アプ開発!J23 -> 0 | J26: =アプ開発!K23 -> 0
C27: サービス | D27: =アプ開発!E29 -> 0 | E27: =アプ開発!F29 -> 0 | F27: =アプ開発!G29 -> 0 | G27: =アプ開発!H29 -> 0 | H27: =アプ開発!I29 -> 0 | I27: =アプ開発!J29 -> 0 | J27: =アプ開発!K29 -> 0
C28: 計 | D28: =SUM(D24:D27) -> 19366 | E28: =SUM(E24:E27) -> 17024 | F28: =SUM(F24:F27) -> 36390 | G28: =SUM(G24:G27) -> 16562 | H28: =SUM(H24:H27) -> 18937 | I28: =SUM(I24:I27) -> 35499 | J28: =SUM(J24:J27) -> 71889 | L28: 65334 | M28: =J28-L28 -> 6555 | N28: =(J28/L28)-1 -> 0.10033061 | R28: =67/12 -> 5.5833333 | S28: =#REF! -> #REF! | T28: =S28-R28 -> #REF! | U28: =(S28/R28)-1 -> #REF! | V28: 72 | W28: 81 | X28: 72 | Y28: 12 | AC28: =72+10 -> 82 | AD28: 12 | AF28: =SUM(W28)/12 -> 6.75 | AG28: =SUM(X28:Y28)/12 -> 7 | AH28: アプリ開発 | AI28: =AG28/AF28 -> 1.037037 | AJ28: =L28/AF28 -> 9679.1111 | AK28: =J28/AG28 -> 10269.857 | AL28: =AK28/AJ28 -> 1.0610331 | AM28: 105%を目標に見直して
B29: システム基盤グループ | C29: 作成請負 | D29: =シス基盤!E13 -> 13715 | E29: =シス基盤!F13 -> 14415 | F29: =シス基盤!G13 -> 28130 | G29: =シス基盤!H13 -> 14415 | H29: =シス基盤!I13 -> 15457 | I29: =シス基盤!J13 -> 29872 | J29: =シス基盤!K13 -> 58002
C30: 作業請負 | D30: =シス基盤!E19 -> 1950 | E30: =シス基盤!F19 -> 1950 | F30: =シス基盤!G19 -> 3900 | G30: =シス基盤!H19 -> 1950 | H30: =シス基盤!I19 -> 1950 | I30: =シス基盤!J19 -> 3900 | J30: =シス基盤!K19 -> 7800
C31: 派遣 | D31: =シス基盤!E25 -> 2035 | E31: =シス基盤!F25 -> 2035 | F31: =シス基盤!G25 -> 4070 | G31: =シス基盤!H25 -> 2035 | H31: =シス基盤!I25 -> 2093 | I31: =シス基盤!J25 -> 4128 | J31: =シス基盤!K25 -> 8198
C32: サービス | D32: =シス基盤!E31 -> 0 | E32: =シス基盤!F31 -> 0 | F32: =シス基盤!G31 -> 0 | G32: =シス基盤!H31 -> 0 | H32: =シス基盤!I31 -> 0 | I32: =シス基盤!J31 -> 0 | J32: =シス基盤!K31 -> 0
C33: 計 | D33: =SUM(D29:D32) -> 17700 | E33: =SUM(E29:E32) -> 18400 | F33: =SUM(F29:F32) -> 36100 | G33: =SUM(G29:G32) -> 18400 | H33: =SUM(H29:H32) -> 19500 | I33: =SUM(I29:I32) -> 37900 | J33: =SUM(J29:J32) -> 74000 | L33: 67969 | M33: =J33-L33 -> 6031 | N33: =(J33/L33)-1 -> 0.088731628 | R33: =99/12 -> 8.25 | S33: =シス基盤!K35 -> 8 | T33: =S33-R33 -> -0.25 | U33: =(S33/R33)-1 -> -0.03030303 | V33: 99 | W33: 93 | X33: 96 | Y33: 0 | Z33: 105 | AA33: 3 | AC33: 96 | AF33: =SUM(W33)/12 -> 7.75 | AG33: =SUM(X33:Y33)/12 -> 8 | AH33: 基盤 | AI33: =AG33/AF33 -> 1.0322581 | AJ33: =L33/AF33 -> 8770.1935 | AK33: =J33/AG33 -> 9250 | AL33: =AK33/AJ33 -> 1.0547088 | AM33: OK
B35: 全社合計(CO含む) | D35: =SUM(D8,D13,D18,D23,D28,D33) -> 102466 | E35: =SUM(E8,E13,E18,E23,E28,E33) -> 101824 | F35: =SUM(F8,F13,F18,F23,F28,F33) -> 204290 | G35: =SUM(G8,G13,G18,G23,G28,G33) -> 100962 | H35: =SUM(H8,H13,H18,H23,H28,H33) -> 106137 | I35: =SUM(I8,I13,I18,I23,I28,I33) -> 207099 | J35: =SUM(J8,J13,J18,J23,J28,J33) -> 411389 | L35: =SUM(L33,L13,L28,L23,L18,L8) -> 385768 | M35: =J35-L35 -> 25621 | N35: =J35/L35 -> 1.0664156 | R35: =SUM(R8,R18,R23,R28,R33) -> 58.166667 | S35: =SUM(S8,S18,S23,S28,S33) -> #REF! | T35: =S35-R35 -> #REF!
B36: ナトーハイシステムズ合計 | D36: =SUM(D8,D13,D18,D28,D33) -> 98466 | E36: =SUM(E8,E13,E18,E28,E33) -> 97824 | F36: =SUM(F8,E13,F18,F28,F33) -> 189790 | G36: =SUM(G8,G13,G18,G28,G33) -> 96962 | H36: =SUM(H8,H13,H18,H28,H33) -> 102137 | I36: =SUM(I8,I13,I18,I28,I33) -> 199099 | J36: =SUM(J8,J13,J18,J28,J33) -> 395389 | L36: =SUM(L33,L13,L28,L18,L8) -> 370178 | M36: =J36-L36 -> 25211 | N36: =J36/L36 -> 1.0681051 | R36: =657/12 -> 54.75 | S36: =SUM(S8,S18,S28,S33) -> #REF! | T36: =S36-R36 -> #REF!
B37: COネット合計 | D37: =D23 -> 4000 | E37: =E23 -> 4000 | F37: =F23 -> 8000 | G37: =G23 -> 4000 | H37: =H23 -> 4000 | I37: =I23 -> 8000 | J37: =J23 -> 16000 | L37: =L23 -> 15590 | M37: =J37-L37 -> 410 | N37: =J37/L37 -> 1.0262989 | R37: =41/12 -> 3.4166667 | S37: =S23 -> 2 | T37: =S37-R37 -> -1.4166667
L39: 2023売上目標 | M39: 差異 | N39: 伸長率
L40: 409200 | M40: =L35-L40 -> -23432 | N40: =L40/L35-1 -> 0.060741171
B43: 部門名 | C43: ランク | D43: １Q | E43: ２Q | F43: 期計 | G43: ３Q | H43: ４Q | I43: 期計 | J43: 合計 | L43: A～Cランク：受注先がすでに決まっており、継続的など受注角度が高いもの。
B44: 第一システムグループ(サポート) | C44: A～C | D44: =SUM(第一!E19:E24) -> 33260 | E44: =SUM(第一!F19:F24) -> 32710 | F44: =SUM(D44:E44) -> 65970 | G44: =SUM(第一!H19:H24) -> 31570 | H44: =SUM(第一!I19:I24) -> 33140 | I44: =SUM(G44:H44) -> 64710 | J44: =SUM(F44,I44) -> 130680 | L44: Dランク：受注先が決まっており60%超えで受注成功が期待できるもの。または、A～Cランクの案件に追加で60%超えで期待できるもの。
...

Sheet 数字丸め
A1: 部門名 | B1: ランク | C1: １Q | D1: ２Q | E1: 期計 | F1: ３Q | G1: ４Q | H1: 期計 | I1: 合計
A2: 第一システムグループ(サポート) | B2: A～C | C2: =ROUNDDOWN('サマリー（入力禁止）'!D44,-2) -> 33200 | D2: =ROUNDDOWN('サマリー（入力禁止）'!E44,-2) -> 32700 | E2: =SUM(C2:D2) -> 65900 | F2: =ROUNDDOWN('サマリー（入力禁止）'!G44,-2) -> 31500 | G2: =ROUNDDOWN('サマリー（入力禁止）'!H44,-2) -> 33100 | H2: =SUM(F2:G2) -> 64600 | I2: =SUM(H2,E2) -> 130500
B3: D | C3: =ROUNDDOWN('サマリー（入力禁止）'!D45,-2) -> 0 | D3: =ROUNDDOWN('サマリー（入力禁止）'!E45,-2) -> 400 | E3: =SUM(C3:D3) -> 400 | F3: =ROUNDDOWN('サマリー（入力禁止）'!G45,-2) -> 400 | G3: =ROUNDDOWN('サマリー（入力禁止）'!H45,-2) -> 400 | H3: =SUM(F3:G3) -> 800 | I3: =SUM(E3,H3) -> 1200
B4: E,F | C4: =ROUNDDOWN('サマリー（入力禁止）'!D47,-2) -> 100 | D4: =ROUNDDOWN('サマリー（入力禁止）'!E47,-2) -> 100 | E4: =SUM(C4:D4) -> 200 | F4: =ROUNDDOWN('サマリー（入力禁止）'!G47,-2) -> 1300 | G4: =ROUNDDOWN('サマリー（入力禁止）'!H47,-2) -> 1400 | H4: =SUM(F4:G4) -> 2700 | I4: =SUM(H4,E4) -> 2900
A5: 第一システムグループ（開発） | B5: A～C | C5: =ROUNDDOWN('サマリー（入力禁止）'!D50,-2) -> 3900 | D5: =ROUNDDOWN('サマリー（入力禁止）'!E50,-2) -> 4000 | E5: =SUM(C5:D5) -> 7900 | F5: =ROUNDDOWN('サマリー（入力禁止）'!G50,-2) -> 3600 | G5: =ROUNDDOWN('サマリー（入力禁止）'!H50,-2) -> 3600 | H5: =SUM(F5:G5) -> 7200 | I5: =SUM(H5,E5) -> 15100
B6: D | C6: =ROUNDDOWN('サマリー（入力禁止）'!D51,-2) -> 1800 | D6: =ROUNDDOWN('サマリー（入力禁止）'!E51,-2) -> 2700 | E6: =SUM(C6:D6) -> 4500 | F6: =ROUNDDOWN('サマリー（入力禁止）'!G51,-2) -> 2700 | G6: =ROUNDDOWN('サマリー（入力禁止）'!H51,-2) -> 2700 | H6: =SUM(F6:G6) -> 5400 | I6: =SUM(E6,H6) -> 9900
B7: E,F | C7: =ROUNDDOWN('サマリー（入力禁止）'!D53,-2) -> 700 | D7: =ROUNDDOWN('サマリー（入力禁止）'!E53,-2) -> 800 | E7: =SUM(C7:D7) -> 1500 | F7: =ROUNDDOWN('サマリー（入力禁止）'!G53,-2) -> 800 | G7: =ROUNDDOWN('サマリー（入力禁止）'!H53,-2) -> 800 | H7: =SUM(F7:G7) -> 1600 | I7: =SUM(H7,E7) -> 3100
A8: 第二システムグループ | B8: A～C | C8: =ROUNDDOWN('サマリー（入力禁止）'!D56,-2) -> 20400 | D8: =ROUNDDOWN('サマリー（入力禁止）'!E56,-2) -> 20400 | E8: =SUM(C8:D8) -> 40800 | F8: =ROUNDDOWN('サマリー（入力禁止）'!G56,-2) -> 20400 | G8: =ROUNDDOWN('サマリー（入力禁止）'!H56,-2) -> 20400 | H8: =SUM(F8:G8) -> 40800 | I8: =SUM(H8,E8) -> 81600
B9: D | C9: =ROUNDDOWN('サマリー（入力禁止）'!D57,-2) -> 0 | D9: =ROUNDDOWN('サマリー（入力禁止）'!E57,-2) -> 0 | E9: =SUM(C9:D9) -> 0 | F9: =ROUNDDOWN('サマリー（入力禁止）'!G57,-2) -> 0 | G9: =ROUNDDOWN('サマリー（入力禁止）'!H57,-2) -> 0 | H9: =SUM(F9:G9) -> 0 | I9: =SUM(E9,H9) -> 0
B10: D,E | C10: =ROUNDDOWN('サマリー（入力禁止）'!D59,-2) -> 1100 | D10: =ROUNDDOWN('サマリー（入力禁止）'!E59,-2) -> 1100 | E10: =SUM(C10:D10) -> 2200 | F10: =ROUNDDOWN('サマリー（入力禁止）'!G59,-2) -> 1100 | G10: =ROUNDDOWN('サマリー（入力禁止）'!H59,-2) -> 1100 | H10: =SUM(F10:G10) -> 2200 | I10: =SUM(H10,E10) -> 4400
A11: 第二システムグループ（COネット） | B11: A～C | C11: =ROUNDDOWN('サマリー（入力禁止）'!D62,-2) -> 3800 | D11: =ROUNDDOWN('サマリー（入力禁止）'!E62,-2) -> 3800 | E11: =SUM(C11:D11) -> 7600 | F11: =ROUNDDOWN('サマリー（入力禁止）'!G62,-2) -> 3800 | G11: =ROUNDDOWN('サマリー（入力禁止）'!H62,-2) -> 3800 | H11: =SUM(F11:G11) -> 7600 | I11: =SUM(H11,E11) -> 15200
B12: D | C12: =ROUNDDOWN('サマリー（入力禁止）'!D63,-2) -> 0 | D12: =ROUNDDOWN('サマリー（入力禁止）'!E63,-2) -> 0 | E12: =SUM(C12:D12) -> 0 | F12: =ROUNDDOWN('サマリー（入力禁止）'!G63,-2) -> 0 | G12: =ROUNDDOWN('サマリー（入力禁止）'!H63,-2) -> 0 | H12: =SUM(F12:G12) -> 0 | I12: =SUM(E12,H12) -> 0
B13: D,E | C13: =ROUNDDOWN('サマリー（入力禁止）'!D65,-2) -> 100 | D13: =ROUNDDOWN('サマリー（入力禁止）'!E65,-2) -> 100 | E13: =SUM(C13:D13) -> 200 | F13: =ROUNDDOWN('サマリー（入力禁止）'!G65,-2) -> 100 | G13: =ROUNDDOWN('サマリー（入力禁止）'!H65,-2) -> 100 | H13: =SUM(F13:G13) -> 200 | I13: =SUM(H13,E13) -> 400
A14: アプリ開発グループ | B14: A～C | C14: =ROUNDDOWN('サマリー（入力禁止）'!D68,-2) -> 19300 | D14: =ROUNDDOWN('サマリー（入力禁止）'!E68,-2) -> 17000 | E14: =SUM(C14:D14) -> 36300 | F14: =ROUNDDOWN('サマリー（入力禁止）'!G68,-2) -> 16500 | G14: =ROUNDDOWN('サマリー（入力禁止）'!H68,-2) -> 18900 | H14: =SUM(F14:G14) -> 35400 | I14: =SUM(H14,E14) -> 71700
B15: D | C15: =ROUNDDOWN('サマリー（入力禁止）'!D69,-2) -> 700 | D15: =ROUNDDOWN('サマリー（入力禁止）'!E69,-2) -> 700 | E15: =SUM(C15:D15) -> 1400 | F15: =ROUNDDOWN('サマリー（入力禁止）'!G69,-2) -> 700 | G15: =ROUNDDOWN('サマリー（入力禁止）'!H69,-2) -> 700 | H15: =SUM(F15:G15) -> 1400 | I15: =SUM(E15,H15) -> 2800
B16: D,E | C16: =ROUNDDOWN('サマリー（入力禁止）'!D71,-2) -> 400 | D16: =ROUNDDOWN('サマリー（入力禁止）'!E71,-2) -> 400 | E16: =SUM(C16:D16) -> 800 | F16: =ROUNDDOWN('サマリー（入力禁止）'!G71,-2) -> 1000 | G16: =ROUNDDOWN('サマリー（入力禁止）'!H71,-2) -> 900 | H16: =SUM(F16:G16) -> 1900 | I16: =SUM(H16,E16) -> 2700
A17: システム基盤グループ | B17: A～C | C17: =ROUNDDOWN('サマリー（入力禁止）'!D74,-2) -> 17600 | D17: =ROUNDDOWN('サマリー（入力禁止）'!E74,-2) -> 17600 | E17: =SUM(C17:D17) -> 35200 | F17: =ROUNDDOWN('サマリー（入力禁止）'!G74,-2) -> 17600 | G17: =ROUNDDOWN('サマリー（入力禁止）'!H74,-2) -> 17600 | H17: =SUM(F17:G17) -> 35200 | I17: =SUM(H17,E17) -> 70400
B18: D | C18: =ROUNDDOWN('サマリー（入力禁止）'!D75,-2) -> 0 | D18: =ROUNDDOWN('サマリー（入力禁止）'!E75,-2) -> 400 | E18: =SUM(C18:D18) -> 400 | F18: =ROUNDDOWN('サマリー（入力禁止）'!G75,-2) -> 400 | G18: =ROUNDDOWN('サマリー（入力禁止）'!H75,-2) -> 400 | H18: =SUM(F18:G18) -> 800 | I18: =SUM(E18,H18) -> 1200
B19: D,E | C19: =ROUNDDOWN('サマリー（入力禁止）'!D77,-2) -> 0 | D19: =ROUNDDOWN('サマリー（入力禁止）'!E77,-2) -> 300 | E19: =SUM(C19:D19) -> 300 | F19: =ROUNDDOWN('サマリー（入力禁止）'!G77,-2) -> 300 | G19: =ROUNDDOWN('サマリー（入力禁止）'!H77,-2) -> 1400 | H19: =SUM(F19:G19) -> 1700 | I19: =SUM(H19,E19) -> 2000
A20: 合計 | C20: =SUM(C2:C19) -> 103100 | D20: =SUM(D2:D19) -> 102500 | E20: =SUM(E2:E19) -> 205600 | F20: =SUM(F2:F19) -> 102200 | G20: =SUM(G2:G19) -> 107300 | H20: =SUM(H2:H19) -> 209500 | I20: =SUM(I2:I19) -> 415100
A24: S | B24: ランク | C24: １Q | D24: ２Q | E24: 期計 | F24: ３Q | G24: ４Q | H24: 期計 | I24: 合計
A25: 第一システムグループ(サポート) | C25: =SUM(C2:C4) -> 33300 | D25: =SUM(D2:D4) -> 33200 | E25: =SUM(C25:D25) -> 66500 | F25: =SUM(F2:F4) -> 33200 | G25: =SUM(G2:G4) -> 34900 | H25: =SUM(F25:G25) -> 68100 | I25: =SUM(E25,H25) -> 134600
A26: 第一システムグループ(開発) | C26: =SUM(C5:C7) -> 6400 | D26: =SUM(D5:D7) -> 7500 | E26: =SUM(C26:D26) -> 13900 | F26: =SUM(F5:F7) -> 7100 | G26: =SUM(G5:G7) -> 7100 | H26: =SUM(F26:G26) -> 14200 | I26: =SUM(E26,H26) -> 28100
A27: 第二システムグループ | C27: =SUM(C8:C10) -> 21500 | D27: =SUM(D8:D10) -> 21500 | E27: =SUM(C27:D27) -> 43000 | F27: =SUM(F8:F10) -> 21500 | G27: =SUM(G8:G10) -> 21500 | H27: =SUM(F27:G27) -> 43000 | I27: =SUM(E27,H27) -> 86000
A28: アプリ開発グループ | C28: =SUM(C14:C16) -> 20400 | D28: =SUM(D14:D16) -> 18100 | E28: =SUM(C28:D28) -> 38500 | F28: =SUM(F14:F16) -> 18200 | G28: =SUM(G14:G16) -> 20500 | H28: =SUM(F28:G28) -> 38700 | I28: =SUM(E28,H28) -> 77200
A29: システム基盤グループ | C29: =SUM(C17:C19) -> 17600 | D29: =SUM(D17:D19) -> 18300 | E29: =SUM(C29:D29) -> 35900 | F29: =SUM(F17:F19) -> 18300 | G29: =SUM(G17:G19) -> 19400 | H29: =SUM(F29:G29) -> 37700 | I29: =SUM(E29,H29) -> 73600
A30: 小計 | C30: =SUM(C25:C29) -> 99200 | D30: =SUM(D25:D29) -> 98600 | E30: =SUM(E25:E29) -> 197800 | F30: =SUM(F25:F29) -> 98300 | G30: =SUM(G25:G29) -> 103400 | H30: =SUM(H25:H29) -> 201700 | I30: =SUM(I25:I29) -> 399500
A31: 第二システムグループ（COネット） | C31: =SUM(C11:C13) -> 3900 | D31: =SUM(D11:D13) -> 3900 | E31: =SUM(C31:D31) -> 7800 | F31: =SUM(F11:F13) -> 3900 | G31: =SUM(G11:G13) -> 3900 | H31: =SUM(F31:G31) -> 7800 | I31: =SUM(E31,H31) -> 15600
H32: 合計 | I32: =I30+I31 -> 415100
A35: 予算411,000千円 | O35: 不足予算
A36: SI | C36: １Q | D36: ２Q | E36: 期計 | F36: ３Q | G36: ４Q | H36: 期計 | I36: 合計 | J36: 予算 | K36: 不足予算 | L36: 計 | M36: 微調整 | N36: 丸め予算 | O36: 延べ数 | P36: 比率 | Q36: 金額 | R36: 丸め
A37: 第一システムグループ(サポート) | C37: =第一!E35 -> 33400 | D37: =第一!F35 -> 33300 | E37: =SUM(C37:D37) -> 66700 | F37: =第一!H35 -> 33300 | G37: =第一!I35 -> 35000 | H37: =SUM(F37:G37) -> 68300 | I37: =SUM(E37,H37) -> 135000 | J37: 134390 | K37: =R37 -> 610 | L37: =J37+K37 -> 135000 | M37: 0 | N37: =L37+M37 -> 135000 | O37: 240 | P37: =O37/$O$42 -> 0.39215686 | Q37: =P37*$K$42 -> 827.45098 | R37: 610
A38: 第一システムグループ(開発) | C38: =第一開発!E35 -> 6500 | D38: =第一開発!F35 -> 7600 | E38: =SUM(C38:D38) -> 14100 | F38: =第一開発!H35 -> 7200 | G38: =第一開発!I35 -> 7200 | H38: =SUM(F38:G38) -> 14400 | I38: =SUM(E38,H38) -> 28500 | J38: 28140 | K38: =R38 -> 360 | L38: =J38+K38 -> 28500 | M38: 0 | N38: =L38+M38 -> 28500 | O38: 60 | P38: =O38/$O$42 -> 0.098039216 | Q38: =P38*$K$42 -> 206.86275 | R38: 360
A39: 第二システムグループ | C39: =第ニ!E29 -> 21500 | D39: =第ニ!F29 -> 21500 | E39: =SUM(C39:D39) -> 43000 | F39: =第ニ!H29 -> 21500 | G39: =第ニ!I29 -> 21500 | H39: =SUM(F39:G39) -> 43000 | I39: =SUM(E39,H39) -> 86000 | J39: 85680 | K39: =R39 -> 320 | L39: =J39+K39 -> 86000 | M39: 0 | N39: =L39+M39 -> 86000 | O39: 132 | P39: =O39/$O$42 -> 0.21568627 | Q39: =P39*$K$42 -> 455.09804 | R39: 320
A40: アプリ開発グループ | C40: =アプ開発!E30 -> 19366 | D40: =アプ開発!F30 -> 17024 | E40: =SUM(C40:D40) -> 36390 | F40: =アプ開発!H30 -> 16562 | G40: =アプ開発!I30 -> 18937 | H40: =SUM(F40:G40) -> 35499 | I40: =SUM(E40,H40) -> 71889 | J40: 71082 | K40: =R40 -> 418 | L40: =J40+K40 -> 71500 | M40: 0 | N40: =L40+M40 -> 71500 | O40: 84 | P40: =O40/$O$42 -> 0.1372549 | Q40: =P40*$K$42 -> 289.60784 | R40: 418
A41: システム基盤グループ | C41: =シス基盤!E32 -> 17700 | D41: =シス基盤!F32 -> 18400 | E41: =SUM(C41:D41) -> 36100 | F41: =シス基盤!H32 -> 18400 | G41: =シス基盤!I32 -> 19500 | H41: =SUM(F41:G41) -> 37900 | I41: =SUM(E41,H41) -> 74000 | J41: 73598 | K41: =R41 -> 402 | L41: =J41+K41 -> 74000 | M41: 0 | N41: =L41+M41 -> 74000 | O41: 96 | P41: =O41/$O$42 -> 0.15686275 | Q41: =P41*$K$42 -> 330.98039 | R41: 402
A42: 小計 | C42: =SUM(C37:C41) -> 98466 | D42: =SUM(D37:D41) -> 97824 | E42: =SUM(C42:D42) -> 196290 | F42: =SUM(F37:F41) -> 96962 | G42: =SUM(G37:G41) -> 102137 | H42: =SUM(F42:G42) -> 199099 | I42: =SUM(E42,H42) -> 395389 | J42: =SUM(J37:J41) -> 392890 | K42: =L42-J42 -> 2110 | L42: 395000 | M42: =SUM(M37:M41) -> 0 | N42: =L42+M42 -> 395000 | O42: =SUM(O37:O41) -> 612 | P42: =SUM(P37:P41) -> 1 | Q42: =SUM(Q37:Q41) -> 2110 | R42: =SUM(R37:R41) -> 2110
A43: 第二システムグループ（COネット） | C43: ='第ニ (CO)'!E29 -> 4000 | D43: ='第ニ (CO)'!F29 -> 4000 | E43: =SUM(C43:D43) -> 8000 | F43: ='第ニ (CO)'!H29 -> 4000 | G43: ='第ニ (CO)'!I29 -> 4000 | H43: =SUM(F43:G43) -> 8000 | I43: =SUM(E43,H43) -> 16000 | J43: 16000 | K43: 0 | L43: =J43+K43 -> 16000 | N43: =L43+M43 -> 16000
E44: =E42+E43 -> 204290 | H44: =H42+H43 -> 207099 | I44: =I42+I43 -> 411389 | J44: =SUM(J42:J43) -> 408890 | K44: =L44-J44 -> 2110 | L44: =SUM(L42:L43) -> 411000 | N44: =L44+M44 -> 411000
M46: 2024売上 | N46: ='サマリー（入力禁止）'!L36 -> 370178 | O46: 延べ数 | P46: 比率 | Q46: 延べ数予算 | R46: 予算 | S46: 差額 | T46: 予算率
...

Sheet 第一
A1: 2025年度予算
B2: ■ | C2: 第一システムグループ | K2: 単位：千円
B3: 【売上計画・見込】 | E3: 7～9月 | F3: 10～12月 | H3: 1～3月 | I3: 4～6月 | M3: 開発
B4: 作業項目／プロジェクト名 | D4: 顧客区分 | E4: １Q | F4: ２Q | G4: 計 | H4: ３Q | I4: ４Q | J4: 計 | K4: 合計 | M4: 2023年度 | O4: 実績 | P4: 33538 | Q4: 千円
B5: 作成請負 | O5: 目標値 | P5: 39000 | Q5: 千円
M7: 2024年度 | N7: 前年実績5%up値 | O7: 目標値 | P7: 35200 | Q7: 千円
O8: Q毎 | P8: 8800 | Q8: 千円
C11: 小計 | E11: =SUM(E6:E10) -> 0 | F11: =SUM(F6:F10) -> 0 | G11: =SUM(G6:G10) -> 0 | H11: =SUM(H6:H10) -> 0 | I11: =SUM(I6:I10) -> 0 | J11: =SUM(J6:J10) -> 0 | K11: =SUM(K6:K10) -> 0
B12: 作業請負
G13: =SUM(E13:F13) -> 0 | J13: =SUM(H13:I13) -> 0 | K13: =SUM(G13,J13) -> 0 | N13: 原価(月あたりの１人分)
G14: =SUM(E14:F14) -> 0 | J14: =SUM(H14:I14) -> 0 | K14: =SUM(G14,J14) -> 0 | N14: 3,100*170H= | P14: 527 | Q14: 千円
G15: =SUM(E15:F15) -> 0 | J15: =SUM(H15:I15) -> 0 | K15: =SUM(G15,J15) -> 0 | N15: 5名 | P15: 2635 | Q15: 千円
G16: =SUM(E16:F16) -> 0 | J16: =SUM(H16:I16) -> 0 | K16: =SUM(G16,J16) -> 0 | N16: ３ヶ月 | P16: 7905 | Q16: 千円
C17: 小計 | E17: =SUM(E13:E16) -> 0 | F17: =SUM(F13:F16) -> 0 | G17: =SUM(G13:G16) -> 0 | H17: =SUM(H13:H16) -> 0 | I17: =SUM(I13:I16) -> 0 | J17: =SUM(J13:J16) -> 0 | K17: =SUM(K13:K16) -> 0
B18: 派遣
C19: サポートデスク（FTI） | D19: 富士通関連 | E19: 14320 | F19: 13900 | G19: =SUM(E19:F19) -> 28220 | H19: 13070 | I19: 14110 | J19: =SUM(H19:I19) -> 27180 | K19: =SUM(G19,J19) -> 55400
C20: サポートデスク（CSL） | D20: 富士通関連 | E20: 6640 | F20: 6350 | G20: =SUM(E20:F20) -> 12990 | H20: 6250 | I20: 6440 | J20: =SUM(H20:I20) -> 12690 | K20: =SUM(G20,J20) -> 25680 | N20: 2024年度売上 | P20: 稼働下方修正
C21: サポートデスク（Vmware）（CSL） | D21: 富士通関連 | E21: 4660 | F21: 4460 | G21: =SUM(E21:F21) -> 9120 | H21: 4390 | I21: 4530 | J21: =SUM(H21:I21) -> 8920 | K21: =SUM(G21,J21) -> 18040 | N21: 127932 | P21: WIN 据え
C22: ARCserve ベンダーサポート | D22: 富士通関連 | E22: 1750 | F22: 1670 | G22: =SUM(E22:F22) -> 3420 | H22: 1650 | I22: 1700 | J22: =SUM(H22:I22) -> 3350 | K22: =SUM(G22,J22) -> 6770 | N22: 単金 | P22: BO -2H/月
C23: Gloviaサポート | D23: 富士通関連 | E23: 1920 | F23: 1870 | G23: =SUM(E23:F23) -> 3790 | H23: 1750 | I23: 1900 | J23: =SUM(H23:I23) -> 3650 | K23: =SUM(G23,J23) -> 7440 | N23: 一人50円↑目標2Ｑ | P23: VM 据え
C24: お客様Webコンテンツ編集 | D24: 富士通関連 | E24: 3970 | F24: 4460 | G24: =SUM(E24:F24) -> 8430 | H24: 4460 | I24: 4460 | J24: =SUM(H24:I24) -> 8920 | K24: =SUM(G24,J24) -> 17350 | N24: 増員 | P24: WEB -5H/月
C25: 努力目標（単金UP) | D25: 努力目標 | E25: 0 | F25: 440 | G25: =SUM(E25:F25) -> 440 | H25: 420 | I25: 450 | J25: =SUM(H25:I25) -> 870 | K25: =SUM(G25,J25) -> 1310 | N25: 3Ｑ以降 | P25: GLO 据え
C26: 努力目標（1名増員） | D26: 努力目標 | E26: 0 | F26: 0 | G26: =SUM(E26:F26) -> 0 | H26: 1200 | I26: 1200 | J26: =SUM(H26:I26) -> 2400 | K26: =SUM(G26,J26) -> 2400
C27: 努力目標（追加予算） | D27: 努力目標 | E27: 140 | F27: 150 | G27: =SUM(E27:F27) -> 290 | H27: 110 | I27: 210 | J27: =SUM(H27:I27) -> 320 | K27: =SUM(G27,J27) -> 610
C28: 小計 | E28: =SUM(E19:E27) -> 33400 | F28: =SUM(F19:F27) -> 33300 | G28: =SUM(G19:G27) -> 66700 | H28: =SUM(H19:H27) -> 33300 | I28: =SUM(I19:I27) -> 35000 | J28: =SUM(J19:J27) -> 68300 | K28: =SUM(K19:K27) -> 135000
B29: サービス（自主ビなど）
G30: =SUM(E30:F30) -> 0 | J30: =SUM(H30:I30) -> 0 | K30: =SUM(G30,J30) -> 0
G31: =SUM(E31:F31) -> 0 | J31: =SUM(H31:I31) -> 0 | K31: =SUM(G31,J31) -> 0
G32: =SUM(E32:F32) -> 0 | J32: =SUM(H32:I32) -> 0 | K32: =SUM(G32,J32) -> 0
G33: =SUM(E33:F33) -> 0 | J33: =SUM(H33:I33) -> 0 | K33: =SUM(G33,J33) -> 0
C34: 小計 | E34: =SUM(E30:E33) -> 0 | F34: =SUM(F30:F33) -> 0 | G34: =SUM(G30:G33) -> 0 | H34: =SUM(H30:H33) -> 0 | I34: =SUM(I30:I33) -> 0 | J34: =SUM(J30:J33) -> 0 | K34: =SUM(K30:K33) -> 0
C35: 合計 | E35: =SUM(E11,E17,E28,E34) -> 33400 | F35: =SUM(F11,F17,F28,F34) -> 33300 | G35: =SUM(G11,G17,G28,G34) -> 66700 | H35: =SUM(H11,H17,H28,H34) -> 33300 | I35: =SUM(I11,I17,I28,I34) -> 35000 | J35: =SUM(J11,J17,J28,J34) -> 68300 | K35: =SUM(K11,K17,K28,K34) -> 135000
B37: 【要員計画】
C38: 要員数 | E38: 20 | F38: 20 | G38: =AVERAGE(E38:F38) -> 20 | H38: 21 | I38: 21 | J38: =AVERAGE(H38:I38) -> 21 | K38: =AVERAGE(G38,J38) -> 20.5
C39: 一人当たりの売上 | E39: =IF(E38<>0,E35/E38,0) -> 1670 | F39: =IF(F38<>0,F35/F38,0) -> 1665 | G39: =SUM(E39:F39) -> 3335 | H39: =IF(H38<>0,H35/H38,0) -> 1585.7143 | I39: =IF(I38<>0,I35/I38,0) -> 1666.6667 | J39: =SUM(H39:I39) -> 3252.381 | K39: =SUM(G39,J39) -> 6587.381
C40: 一人当たりの売上（月） | E40: =E39/3 -> 556.66667 | F40: =F39/3 -> 555 | G40: =G39/6 -> 555.83333 | H40: =H39/3 -> 528.57143 | I40: =I39/3 -> 555.55556 | J40: =J39/6 -> 542.06349 | K40: =K39/12 -> 548.94841

Sheet 第一開発
A1: 2025年度予算
B2: ■ | C2: 第一システムグループ | K2: 単位：千円
B3: 【売上計画・見込】 | E3: 7～9月 | F3: 10～12月 | H3: 1～3月 | I3: 4～6月 | M3: 開発
B4: 作業項目／プロジェクト名 | D4: 顧客区分 | E4: １Q | F4: ２Q | G4: 計 | H4: ３Q | I4: ４Q | J4: 計 | K4: 合計 | M4: 2023年度 | O4: 実績 | P4: 33538 | Q4: 千円
B5: 作成請負 | O5: 目標値 | P5: 39000 | Q5: 千円
C6: 自治体SD/GSSD開発関連 | D6: 富士通 | E6: 2300 | F6: 2400 | G6: =SUM(E6:F6) -> 4700 | H6: 2000 | I6: 2000 | J6: =SUM(H6:I6) -> 4000 | K6: =SUM(G6,J6) -> 8700
C7: ezSDS保守 | D7: 富士通 | E7: 1685 | F7: 1685 | G7: =SUM(E7:F7) -> 3370 | H7: 1685 | I7: 1685 | J7: =SUM(H7:I7) -> 3370 | K7: =SUM(G7,J7) -> 6740 | M7: 2024年度 | N7: 前年実績5%up値 | O7: 目標値 | P7: 35200 | Q7: 千円
C8: ニフティ対応 | D8: 自社顧客 | E8: 1800 | F8: 2700 | G8: =SUM(E8:F8) -> 4500 | H8: 2700 | I8: 2700 | J8: =SUM(H8:I8) -> 5400 | K8: =SUM(G8,J8) -> 9900 | O8: Q毎 | P8: 8800 | Q8: 千円
C10: 他の開発作業 | D10: 努力目標 | E10: 700 | F10: 700 | G10: =SUM(E10:F10) -> 1400 | H10: 700 | I10: 700 | J10: =SUM(H10:I10) -> 1400 | K10: =SUM(G10,J10) -> 2800
C11: 努力目標（追加予算） | D11: 努力目標 | E11: 15 | F11: 115 | G11: =SUM(E11:F11) -> 130 | H11: 115 | I11: 115 | J11: =SUM(H11:I11) -> 230 | K11: =SUM(G11,J11) -> 360
C12: 小計 | E12: =SUM(E6:E11) -> 6500 | F12: =SUM(F6:F11) -> 7600 | G12: =SUM(G6:G11) -> 14100 | H12: =SUM(H6:H11) -> 7200 | I12: =SUM(I6:I11) -> 7200 | J12: =SUM(J6:J11) -> 14400 | K12: =SUM(K6:K11) -> 28500
B13: 作業請負
G14: =SUM(E14:F14) -> 0 | J14: =SUM(H14:I14) -> 0 | K14: =SUM(G14,J14) -> 0 | N14: 原価(月あたりの１人分)
G15: =SUM(E15:F15) -> 0 | J15: =SUM(H15:I15) -> 0 | K15: =SUM(G15,J15) -> 0 | N15: 3,100*170H= | P15: 527 | Q15: 千円
G16: =SUM(E16:F16) -> 0 | J16: =SUM(H16:I16) -> 0 | K16: =SUM(G16,J16) -> 0 | N16: 5名 | P16: 2635 | Q16: 千円
G17: =SUM(E17:F17) -> 0 | J17: =SUM(H17:I17) -> 0 | K17: =SUM(G17,J17) -> 0 | N17: ３ヶ月 | P17: 7905 | Q17: 千円
C18: 小計 | E18: =SUM(E14:E17) -> 0 | F18: =SUM(F14:F17) -> 0 | G18: =SUM(G14:G17) -> 0 | H18: =SUM(H14:H17) -> 0 | I18: =SUM(I14:I17) -> 0 | J18: =SUM(J14:J17) -> 0 | K18: =SUM(K14:K17) -> 0
B19: 派遣
N21: 2024年度売上 | P21: 稼働下方修正
N22: 127932 | P22: WIN 据え
N23: 単金 | P23: BO -2H/月
N24: 一人50円↑目標2Ｑ | P24: VM 据え
N25: 増員 | P25: WEB -5H/月
N26: 3Ｑ以降 | P26: GLO 据え
C28: 小計 | E28: =SUM(E20:E27) -> 0 | F28: =SUM(F20:F27) -> 0 | G28: =SUM(G20:G27) -> 0 | H28: =SUM(H20:H27) -> 0 | I28: =SUM(I20:I27) -> 0 | J28: =SUM(J20:J27) -> 0 | K28: =SUM(K20:K27) -> 0
B29: サービス（自主ビなど）
G30: =SUM(E30:F30) -> 0 | J30: =SUM(H30:I30) -> 0 | K30: =SUM(G30,J30) -> 0
G31: =SUM(E31:F31) -> 0 | J31: =SUM(H31:I31) -> 0 | K31: =SUM(G31,J31) -> 0
G32: =SUM(E32:F32) -> 0 | J32: =SUM(H32:I32) -> 0 | K32: =SUM(G32,J32) -> 0
G33: =SUM(E33:F33) -> 0 | J33: =SUM(H33:I33) -> 0 | K33: =SUM(G33,J33) -> 0
C34: 小計 | E34: =SUM(E30:E33) -> 0 | F34: =SUM(F30:F33) -> 0 | G34: =SUM(G30:G33) -> 0 | H34: =SUM(H30:H33) -> 0 | I34: =SUM(I30:I33) -> 0 | J34: =SUM(J30:J33) -> 0 | K34: =SUM(K30:K33) -> 0
C35: 合計 | E35: =SUM(E12,E18,E28,E34) -> 6500 | F35: =SUM(F12,F18,F28,F34) -> 7600 | G35: =SUM(G12,G18,G28,G34) -> 14100 | H35: =SUM(H12,H18,H28,H34) -> 7200 | I35: =SUM(I12,I18,I28,I34) -> 7200 | J35: =SUM(J12,J18,J28,J34) -> 14400 | K35: =SUM(K12,K18,K28,K34) -> 28500
B37: 【要員計画】
C38: 要員数 | E38: 5 | F38: 5 | G38: =AVERAGE(E38:F38) -> 5 | H38: 5 | I38: 5 | J38: =AVERAGE(H38:I38) -> 5 | K38: =AVERAGE(G38,J38) -> 5
C39: 一人当たりの売上 | E39: =IF(E38<>0,E35/E38,0) -> 1300 | F39: =IF(F38<>0,F35/F38,0) -> 1520 | G39: =SUM(E39:F39) -> 2820 | H39: =IF(H38<>0,H35/H38,0) -> 1440 | I39: =IF(I38<>0,I35/I38,0) -> 1440 | J39: =SUM(H39:I39) -> 2880 | K39: =SUM(G39,J39) -> 5700
C40: 一人当たりの売上（月） | E40: =E39/3 -> 433.33333 | F40: =F39/3 -> 506.66667 | G40: =G39/6 -> 470 | H40: =H39/3 -> 480 | I40: =I39/3 -> 480 | J40: =J39/6 -> 480 | K40: =K39/12 -> 475

Sheet 第ニ
A1: 2025年度予算
B2: ■ | C2: 第二システムグループ | K2: 単位：千円
B3: 【売上計画・見込】 | E3: 7～9月 | F3: 10～12月 | H3: 1～3月 | I3: 4～6月
B4: 作業項目／プロジェクト名 | D4: 顧客区分 | E4: １Q | F4: ２Q | G4: 計 | H4: ３Q | I4: ４Q | J4: 計 | K4: 合計
B5: 作成請負
C6: セキュアゲートウェイ | D6: 富士通 | E6: 20400 | F6: 20400 | G6: 40800 | H6: 20400 | I6: 20400 | J6: 40800 | K6: 81600
C7: セキュアゲートウェイ(スポット) | D7: 努力目標 | E7: 1020 | F7: 1020 | G7: 2040 | H7: 1020 | I7: 1020 | J7: 2040 | K7: 4080
C8: 努力目標（追加予算） | D8: 努力目標 | E8: 80 | F8: 80 | G8: 160 | H8: 80 | I8: 80 | J8: =SUM(H8:I8) -> 160 | K8: =G8+J8 -> 320
G9: 0 | J9: 0 | K9: 0
C10: 小計 | E10: =SUM(E6:E9) -> 21500 | F10: =SUM(F6:F9) -> 21500 | G10: =SUM(G6:G9) -> 43000 | H10: =SUM(H6:H9) -> 21500 | I10: =SUM(I6:I9) -> 21500 | J10: =SUM(J6:J9) -> 43000 | K10: =SUM(K6:K9) -> 86000
B11: 作業請負
G12: 0 | J12: 0 | K12: 0
G13: 0 | J13: 0 | K13: 0
G14: 0 | J14: 0 | K14: 0
G15: 0 | J15: 0 | K15: 0
C16: 小計 | E16: 0 | F16: 0 | G16: 0 | H16: 0 | I16: 0 | J16: 0 | K16: 0
B17: 派遣
G18: 0 | J18: 0 | K18: 0
G19: 0 | J19: 0 | K19: 0
G20: 0 | J20: 0 | K20: 0
G21: 0 | J21: 0 | K21: 0
C22: 小計 | E22: 0 | F22: 0 | G22: 0 | H22: 0 | I22: 0 | J22: 0 | K22: 0
B23: サービス（自主ビなど）
G24: 0 | J24: 0 | K24: 0
G25: 0 | J25: 0 | K25: 0
G26: 0 | J26: 0 | K26: 0
G27: 0 | J27: 0 | K27: 0
C28: 小計 | E28: 0 | F28: 0 | G28: 0 | H28: 0 | I28: 0 | J28: 0 | K28: 0
C29: 合計 | E29: =SUM(E10,E16,E22,E28) -> 21500 | F29: =SUM(F10,F16,F22,F28) -> 21500 | G29: =SUM(G10,G16,G22,G28) -> 43000 | H29: =SUM(H10,H16,H22,H28) -> 21500 | I29: =SUM(I10,I16,I22,I28) -> 21500 | J29: =SUM(J10,J16,J22,J28) -> 43000 | K29: =SUM(K10,K16,K22,K28) -> 86000
B31: 【要員計画】
C32: 要員数 | E32: 11 | F32: 11 | G32: 11 | H32: 11 | I32: 11 | J32: 11 | K32: 11
C33: 一人当たりの売上 | E33: =E29/E32 -> 1954.5455 | F33: =F29/F32 -> 1954.5455 | G33: =G29/G32 -> 3909.0909 | H33: =H29/H32 -> 1954.5455 | I33: =I29/I32 -> 1954.5455 | J33: =J29/J32 -> 3909.0909 | K33: =K29/K32 -> 7818.1818
C34: 一人当たりの売上（月） | E34: =E33/3 -> 651.51515 | F34: =F33/3 -> 651.51515 | G34: =G33/6 -> 651.51515 | H34: =H33/3 -> 651.51515 | I34: =I33/3 -> 651.51515 | J34: =J33/6 -> 651.51515 | K34: =K33/12 -> 651.51515

Sheet 第ニ (CO)
A1: 2025年度予算
B2: ■ | C2: 第二システムグループ | K2: 単位：千円
B3: 【売上計画・見込】 | E3: 7～9月 | F3: 10～12月 | H3: 1～3月 | I3: 4～6月
B4: 作業項目／プロジェクト名 | D4: 顧客区分 | E4: １Q | F4: ２Q | G4: 計 | H4: ３Q | I4: ４Q | J4: 計 | K4: 合計
B5: 作成請負
C6: セキュアゲートウェイ | D6: 富士通 | E6: 3897 | F6: 3897 | G6: =SUM(E6:F6) -> 7794 | H6: 3897 | I6: 3897 | J6: =SUM(H6:I6) -> 7794 | K6: =SUM(J6,G6) -> 15588
C7: 努力目標（追加予算） | D7: 努力目標 | E7: 103 | F7: 103 | G7: =SUM(E7:F7) -> 206 | H7: 103 | I7: 103 | J7: =SUM(H7:I7) -> 206 | K7: =SUM(J7,G7) -> 412
G8: 0 | J8: 0 | K8: 0
G9: 0 | J9: 0 | K9: 0
C10: 小計 | E10: =SUM(E6:E9) -> 4000 | F10: =SUM(F6:F9) -> 4000 | G10: =SUM(E10:F10) -> 8000 | H10: =SUM(H6:H9) -> 4000 | I10: =SUM(I6:I9) -> 4000 | J10: =SUM(H10+I10) -> 8000 | K10: =SUM(G10,J10) -> 16000
B11: 作業請負
G12: 0 | J12: 0 | K12: 0
G13: 0 | J13: 0 | K13: 0
G14: 0 | J14: 0 | K14: 0
G15: 0 | J15: 0 | K15: 0
C16: 小計 | E16: 0 | F16: 0 | G16: 0 | H16: 0 | I16: 0 | J16: 0 | K16: 0
B17: 派遣
G18: 0 | J18: 0 | K18: 0
G19: 0 | J19: 0 | K19: 0
G20: 0 | J20: 0 | K20: 0
G21: 0 | J21: 0 | K21: 0
C22: 小計 | E22: 0 | F22: 0 | G22: 0 | H22: 0 | I22: 0 | J22: 0 | K22: 0
B23: サービス（自主ビなど）
G24: 0 | J24: 0 | K24: 0
G25: 0 | J25: 0 | K25: 0
G26: 0 | J26: 0 | K26: 0
G27: 0 | J27: 0 | K27: 0
C28: 小計 | E28: 0 | F28: 0 | G28: 0 | H28: 0 | I28: 0 | J28: 0 | K28: 0
C29: 合計 | E29: =E10 -> 4000 | F29: =F10 -> 4000 | G29: =SUM(E29:F29) -> 8000 | H29: =H10 -> 4000 | I29: =I10 -> 4000 | J29: =SUM(H29+I29) -> 8000 | K29: =SUM(J29,G29) -> 16000
B31: 【要員計画】
C32: 要員数 | E32: 2 | F32: 2 | G32: 2 | H32: 2 | I32: 2 | J32: 2 | K32: 2
C33: 一人当たりの売上 | E33: =E29/E32 -> 2000 | F33: =F29/F32 -> 2000 | G33: =G29/G32 -> 4000 | H33: =H29/H32 -> 2000 | I33: =I29/I32 -> 2000 | J33: =J29/J32 -> 4000 | K33: =K29/K32 -> 8000
C34: 一人当たりの売上（月） | E34: =E33/3 -> 666.66667 | F34: =F33/3 -> 666.66667 | G34: =G33/6 -> 666.66667 | H34: =H33/3 -> 666.66667 | I34: =I33/3 -> 666.66667 | J34: =J33/6 -> 666.66667 | K34: =K33/12 -> 666.66667

Sheet アプ開発
A1: 2026年度予算
B2: ■ | C2: アプリ開発グループ | K2: 単位：千円 | N2: 2025年度実績
B3: 【売上計画・見込】 | E3: 7～9月 | F3: 10～12月 | H3: 1～3月 | I3: 4～6月 | N3: グループ | Q3: １Q | R3: ２Q | S3: 期計 | T3: ３Q | U3: ４Q | V3: 期計 | W3: 合計 | Y3: 2024年度売上見込 | Z3: 0.05
B4: 作業項目／プロジェクト名 | D4: 顧客区分 | E4: １Q | F4: ２Q | G4: 計 | H4: ３Q | I4: ４Q | J4: 計 | K4: 合計 | N4: 第一システムグループ | Q4: 44470000 | R4: 41240000 | S4: 85710000 | T4: 39390000 | U4: 41800000 | V4: 81190000 | W4: 166900000 | Y4: 162755000 | Z4: =Y4+(Y4*$Z$3) -> 170892750
B5: 作成請負 | N5: 第二システムグループ | Q5: 20400000 | R5: 20400000 | S5: 40800000 | T5: 20400000 | U5: 20400000 | V5: 40800000 | W5: 81600000 | Y5: 81600000 | Z5: =Y5+(Y5*$Z$3) -> 85680000
G6: =SUM(E6:F6) -> 0 | J6: =SUM(H6:I6) -> 0 | K6: =SUM(G6,J6) -> 0 | N6: アプリ開発グループ | Q6: 15970000 | R6: 15410000 | S6: 31380000 | T6: 15410000 | U6: 15410000 | V6: 30820000 | W6: 62200000 | Y6: 65619000 | Z6: =Y6+(Y6*$Z$3) -> 68899950
G7: =SUM(E7:F7) -> 0 | J7: =SUM(H7:I7) -> 0 | K7: =SUM(G7,J7) -> 0 | N7: システム基盤グループ | Q7: 20800000 | R7: 22300000 | S7: 43100000 | T7: 22300000 | U7: 22300000 | V7: 44600000 | W7: 87700000 | Y7: 73819000 | Z7: =Y7+(Y7*$Z$3) -> 77509950 | AA7: =SUM(Z4:Z7) -> 402982650 | AB7: 合計
G8: =SUM(E8:F8) -> 0 | J8: =SUM(H8:I8) -> 0 | K8: =SUM(G8,J8) -> 0 | X8: CO | Y8: 13568000 | Z8: =Y8+(Y8*$Z$3) -> 14246400 | AA8: =SUM(AA7,Z8) -> 417229050 | AB8: 合計CO込み
G9: =SUM(E9:F9) -> 0 | J9: =SUM(H9:I9) -> 0 | K9: =SUM(G9,J9) -> 0 | N9: 2024年度実績
C10: 小計 | E10: =SUM(E6:E9) -> 0 | F10: =SUM(F6:F9) -> 0 | G10: =SUM(G6:G9) -> 0 | H10: =SUM(H6:H9) -> 0 | I10: =SUM(I6:I9) -> 0 | J10: =SUM(J6:J9) -> 0 | K10: =SUM(K6:K9) -> 0 | N10: アプリ開 | O10: 7月 | P10: 8月 | Q10: 9月 | R10: 10月 | S10: 11月 | T10: 12月 | U10: 1月 | V10: 2月 | W10: 3月 | X10: 4月 | Y10: 5月 | Z10: 6月 | AA10: 合計
B11: 作業請負 | N11: 予算 | O11: 5895667 | P11: 5895667 | Q11: 5895667 | R11: 5895667 | S11: 5895667 | T11: 5895667 | U11: 6066667 | V11: 6066667 | W11: 6066667 | X11: 6033333 | Y11: 6033333 | Z11: 6033333 | AA11: =SUM(O11:Z11) -> 71674002
C12: ニフティ 課金システム | D12: 自社顧客 | E12: =O42+P42+Q42 -> 19366 | F12: =R42+S42+T42 -> 17024 | G12: =SUM(E12:F12) -> 36390 | H12: =U42+V42+W42 -> 16562 | I12: =X42+Y42+Z42 -> 18937 | J12: =SUM(H12:I12) -> 35499 | K12: =SUM(G12,J12) -> 71889 | N12: 見込 | O12: 6622058 | P12: 5878822 | Q12: 5943087 | R12: 5602205 | S12: 5392646 | T12: 5219410 | U12: 5333969 | V12: 5043381 | W12: 5395440 | X12: 5725147 | Y12: 6155059 | Z12: 6155059 | AA12: =SUM(O12:Z12) -> 68466283
C13: ニフティ 課金システム(42H/月) | D13: 努力目標 | E13: =O44+P44+Q44 -> 714 | F13: =R44+S44+T44 -> 714 | G13: =SUM(E13:F13) -> 1428 | H13: =U44+V44+W44+U46+V46+W46 -> 714 | I13: =X44+Y44+Z44+X46+Y46+Z46 -> 714 | J13: =SUM(H13:I13) -> 1428 | K13: =SUM(G13,J13) -> 2856 | N13: 実績 | O13: 6622058 | P13: 5878822 | Q13: 5943087 | R13: 5602205 | S13: 5392646 | T13: 5219410 | U13: 5333969 | V13: 5043381 | W13: 5395440 | X13: 5725147 | Y13: 6155059 | Z13: 6155059 | AA13: =SUM(O13:Z13) -> 68466283
C14: ニフティ 課金システム(新人) | D14: 努力目標 | G14: =SUM(E14:F14) -> 0 | H14: =SUM(U51:W51) -> 513 | I14: =SUM(X51:Z51) -> 513 | J14: =SUM(H14:I14) -> 1026 | K14: =SUM(G14,J14) -> 1026 | N14: 差額予算 | O14: =O13-O11 -> 726391 | P14: =P13-P11 -> -16845 | Q14: =Q13-Q11 -> 47420 | R14: =R13-R11 -> -293462 | S14: =S13-S11 -> -503021 | T14: =T13-T11 -> -676257 | U14: =U13-U11 -> -732698 | V14: =V13-V11 -> -1023286 | ... Z14: =Z13-Z11 -> 121726 | AA14: =SUM(O14:Z14) -> -3207719
C15: ニフティ 課金システム(スポット60H/Q) | D15: 努力目標 | E15: 390 | F15: 390 | G15: =SUM(E15:F15) -> 780 | H15: 390 | I15: 390 | J15: =SUM(H15:I15) -> 780 | K15: =SUM(G15,J15) -> 1560 | N15: 差額見込 | O15: -132911 | P15: -382685 | Q15: 173497 | R15: 344931 | S15: 78919 | T15: 110887 | U15: -372736 | V15: -197720 | W15: -73342 | X15: 440029 | Y15: 87021 | Z15: 799097 | AA15: 874987
C16: 努力目標（追加予算） | D16: 努力目標 | E16: 86 | F16: 86 | G16: =SUM(E16:F16) -> 172 | H16: 173 | I16: 73 | J16: =SUM(H16:I16) -> 246 | K16: =SUM(G16,J16) -> 418
C17: 小計 | E17: 19366 | F17: 17024 | G17: =E17+F17 -> 36390 | H17: 16562 | I17: 18937 | J17: =H17+I17 -> 35499 | K17: =G17+J17 -> 71889
B18: 派遣 | N18: 売上内訳
G19: =SUM(E19:F19) -> 0 | J19: =SUM(H19:I19) -> 0 | K19: =SUM(G19,J19) -> 0 | N19: 請負 | O19: 4448235 | P19: 4255440 | Q19: =5294852-674500 -> 4620352 | R19: =5931911-978500 -> 4953411 | S19: =5309629-864500 -> 4445129 | T19: =5454117-940500 -> 4513617 | U19: =5446911-969000 -> 4477911 | V19: =5498822-912000 -> 4586822 | W19: =5691617-997000 -> 4694617 | X19: =5521176-969000 -> 4552176 | Y19: =5107646-893000 -> 4214646 | Z19: =4934411-114 -> 4934297 | AA19: =SUM(O19:Z19) -> 54696653
G20: =SUM(E20:F20) -> 0 | J20: =SUM(H20:I20) -> 0 | K20: =SUM(G20,J20) -> 0 | N20: 派遣 | O20: 848854 | P20: 811875 | Q20: 1043145 | R20: 801520 | S20: 1103790 | T20: 1067270 | U20: 709353 | V20: 1005458 | W20: 892041 | X20: 790853 | Y20: 715375 | Z20: 961686 | AA20: =SUM(O20:Z20) -> 10751220
G21: =SUM(E21:F21) -> 0 | J21: =SUM(H21:I21) -> 0 | K21: =SUM(G21,J21) -> 0 | N21: 合計 | O21: =SUM(O19:O20) -> 5297089 | P21: =SUM(P19:P20) -> 5067315 | Q21: =SUM(Q19:Q20) -> 5663497 | R21: =SUM(R19:R20) -> 5754931 | S21: =SUM(S19:S20) -> 5548919 | T21: =SUM(T19:T20) -> 5580887 | U21: =SUM(U19:U20) -> 5187264 | V21: =SUM(V19:V20) -> 5592280 | ... Z21: =SUM(Z19:Z20) -> 5895983 | AA21: =SUM(O21:Z21) -> 65447873 | AC21: 0.05
G22: =SUM(E22:F22) -> 0 | J22: =SUM(H22:I22) -> 0 | K22: =SUM(G22,J22) -> 0 | AB22: ="売上前年比" &AC21 -> 売上前年比0.05 | AC22: =AA21+(AA21*AC21) -> 68720267
C23: 小計 | E23: =SUM(E19:E22) -> 0 | F23: =SUM(F19:F22) -> 0 | G23: =SUM(G19:G22) -> 0 | H23: =SUM(H19:H22) -> 0 | I23: =SUM(I19:I22) -> 0 | J23: =SUM(J19:J22) -> 0 | K23: =SUM(K19:K22) -> 0 | N23: 950000 | O23: 5000 | AB23: 前年度差額 | AC23: =AC22-AA21 -> 3272393.7
B24: サービス（自主ビなど） | N24: 170 | O24: 20
G25: =SUM(E25:F25) -> 0 | J25: =SUM(H25:I25) -> 0 | K25: =SUM(G25,J25) -> 0 | N25: 165 | O25: 7.5 | Q25: 新人 | R25: 140
G26: =SUM(E26:F26) -> 0 | J26: =SUM(H26:I26) -> 0 | K26: =SUM(G26,J26) -> 0 | N26: 5 | Q26: メンバー/1人 | R26: 5
G27: =SUM(E27:F27) -> 0 | J27: =SUM(H27:I27) -> 0 | K27: =SUM(G27,J27) -> 0 | N27: =N25*N26 -> 825
G28: =SUM(E28:F28) -> 0 | J28: =SUM(H28:I28) -> 0 | K28: =SUM(G28,J28) -> 0 | N28: =N27/N24 -> 4.8529412
C29: 小計 | E29: =SUM(E25:E28) -> 0 | F29: =SUM(F25:F28) -> 0 | G29: =SUM(G25:G28) -> 0 | H29: =SUM(H25:H28) -> 0 | I29: =SUM(I25:I28) -> 0 | J29: =SUM(J25:J28) -> 0 | K29: =SUM(K25:K28) -> 0 | N29: =N23*N28 -> 4610294.1
C30: 合計 | E30: =E17 -> 19366 | F30: =F17 -> 17024 | G30: =G17 -> 36390 | H30: =H17 -> 16562 | I30: =I17 -> 18937 | J30: =J17 -> 35499 | K30: =K17 -> 71889
M31: 請負売上 | N31: =AA19 -> 54696653
B32: 【要員計画】 | M32: 平均 | N32: =N31/12 -> 4558054.4
C33: 要員数 | E33: 7 | F33: 7 | G33: =AVERAGE(E33:F33) -> 7 | H33: 7 | I33: 7 | J33: =AVERAGE(H33:I33) -> 7 | K33: =AVERAGE(G33,J33) -> 7 | M33: 人月 | N33: =N32/N23 -> 4.797952 | O33: =N33/N34 -> 0.79965867 | P33: =O33*N24 -> 135.94197
C34: 一人当たりの売上 | E34: =IF(E33<>0,E30/E33,0) -> 2766.5714 | F34: =IF(F33<>0,F30/F33,0) -> 2432 | G34: =SUM(E34:F34) -> 5198.5714 | H34: =IF(H33<>0,H30/H33,0) -> 2366 | I34: =IF(I33<>0,I30/I33,0) -> 2705.2857 | J34: =SUM(H34:I34) -> 5071.2857 | K34: =SUM(G34,J34) -> 10269.857 | M34: 人数 | N34: 6 | O34: 木下、田上、荒木、辰巳、宮本
C35: 一人当たりの売上（月） | E35: =E34/3 -> 922.19048 | F35: =F34/3 -> 810.66667 | G35: =G34/6 -> 866.42857 | H35: =H34/3 -> 788.66667 | I35: =I34/3 -> 901.7619 | J35: =J34/6 -> 845.21429 | K35: =K34/12 -> 855.82143 | N35: 6 | O35: 米村 | P35: =P33*N35 -> 815.65184 | Q35: =P35/N24 -> 4.797952 | R35: =Q35*N23 -> 4558054.4
N39: 丸め | O39: 7月 | P39: 8月 | Q39: 9月 | R39: 10月 | S39: 11月 | T39: 12月 | U39: 1月 | V39: 2月 | W39: 3月 | X39: 4月 | Y39: 5月 | Z39: 6月
O40: 20 | P40: 21 | Q40: 22 | R40: 18 | S40: 22 | T40: 22 | U40: 15 | V40: 22 | W40: 18 | X40: 21 | Y40: 19 | Z40: 23
N41: 派遣 | AA41: =SUM(O41:Z41) -> 0
N42: 請負 | O42: 6953 | P42: 6173 | Q42: 6240 | R42: 5882 | S42: 5662 | T42: 5480 | U42: 5601 | V42: 5296 | W42: 5665 | X42: 6011 | Y42: 6463 | Z42: 6463 | AA42: =SUM(O42:Z42) -> 71889
AA43: =SUM(AA41+AA42) -> 71889 | AB43: 見込合計
...

Sheet シス基盤
A1: 2025年度予算
B2: ■ | C2: システム基盤グループ | K2: 単位：千円
B3: 【売上計画・見込】 | E3: 7～9月 | F3: 10～12月 | H3: 1～3月 | I3: 4～6月
B4: 作業項目／プロジェクト名 | D4: 顧客区分 | E4: １Q | F4: ２Q | G4: 計 | H4: ３Q | I4: ４Q | J4: 計 | K4: 合計
B5: 作成請負
C6: ハロー保守業務 | D6: 富士通 | E6: 8700 | F6: 8700 | G6: =SUM(E6:F6) -> 17400 | H6: 8700 | I6: 8700 | J6: =SUM(H6:I6) -> 17400 | K6: =SUM(G6,J6) -> 34800 | L6: 崎元(80)、山瀬(75)、佐藤(75)、石本(60)
C7: ハロー雇用保険PMO業務 | D7: 富士通 | E7: 2550 | F7: 2550 | G7: =SUM(E7:F7) -> 5100 | H7: 2550 | I7: 2550 | J7: =SUM(H7:I7) -> 5100 | K7: =SUM(G7,J7) -> 10200 | L7: 太田(85)
C8: ハロー拠点設計開発業務 | D8: 富士通 | E8: 2400 | F8: 2400 | G8: =SUM(E8:F8) -> 4800 | H8: 2400 | I8: 2400 | J8: =SUM(H8:I8) -> 4800 | K8: =SUM(G8,J8) -> 9600 | L8: 荒木(80)
C9: ハロー拠点設計開発業務（シフト） | D9: 努力目標 | F9: 450 | G9: =SUM(E9:F9) -> 450 | H9: 450 | I9: 450 | J9: =SUM(H9:I9) -> 900 | K9: =SUM(G9,J9) -> 1350 | L9: 下田予定(65→80)
C10: ハロー保守業務 | D10: 努力目標 | G10: =SUM(E10:F10) -> 0 | I10: 1200 | J10: =SUM(H10:I10) -> 1200 | K10: =SUM(G10,J10) -> 1200 | L10: 崎元(80→85)、山瀬(75→80)、佐藤(75→80)、石本(60→75)：合計300千円
C11: ハロー拠点設計開発業務 | D11: 努力目標 | F11: 150 | G11: =SUM(E11:F11) -> 150 | H11: 150 | I11: 150 | J11: =SUM(H11:I11) -> 300 | K11: =SUM(G11,J11) -> 450 | L11: 荒木(80→85)
C12: 努力目標（追加予算） | D12: 努力目標 | E12: 65 | F12: 165 | G12: =SUM(E12:F12) -> 230 | H12: 165 | I12: 7 | J12: =SUM(H12:I12) -> 172 | K12: =SUM(G12,J12) -> 402
C13: 小計 | E13: =SUM(E6:E12) -> 13715 | F13: =SUM(F6:F12) -> 14415 | G13: =SUM(G6:G12) -> 28130 | H13: =SUM(H6:H12) -> 14415 | I13: =SUM(I6:I12) -> 15457 | J13: =SUM(J6:J12) -> 29872 | K13: =SUM(K6:K12) -> 58002
B14: 作業請負
C15: TAM | D15: 自社顧客 | E15: 1950 | F15: 1950 | G15: =SUM(E15:F15) -> 3900 | H15: 1950 | I15: 1950 | J15: =SUM(H15:I15) -> 3900 | K15: =SUM(G15,J15) -> 7800 | L15: 下田(65)
G16: =SUM(E16:F16) -> 0 | J16: =SUM(H16:I16) -> 0 | K16: =SUM(G16,J16) -> 0
G17: =SUM(E17:F17) -> 0 | J17: =SUM(H17:I17) -> 0 | K17: =SUM(G17,J17) -> 0
G18: =SUM(E18:F18) -> 0 | J18: =SUM(H18:I18) -> 0 | K18: =SUM(G18,J18) -> 0
C19: 小計 | E19: =SUM(E15:E18) -> 1950 | F19: =SUM(F15:F18) -> 1950 | G19: =SUM(G15:G18) -> 3900 | H19: =SUM(H15:H18) -> 1950 | I19: =SUM(I15:I18) -> 1950 | J19: =SUM(J15:J18) -> 3900 | K19: =SUM(K15:K18) -> 7800
B20: 派遣
C21: e-FOCUS | D21: 富士通 | E21: 2035 | F21: 2035 | G21: =SUM(E21:F21) -> 4070 | H21: 2035 | I21: 2035 | J21: =SUM(H21:I21) -> 4070 | K21: =SUM(G21,J21) -> 8140 | L21: 秋築：時給4240x160hx3か月を見込む、2026/4から120円up見込み
C22: 単金Up | D22: 努力目標 | G22: =SUM(E22:F22) -> 0 | I22: 58 | J22: =SUM(H22:I22) -> 58 | K22: =SUM(G22,J22) -> 58
G23: =SUM(E23:F23) -> 0 | J23: =SUM(H23:I23) -> 0 | K23: =SUM(G23,J23) -> 0
G24: =SUM(E24:F24) -> 0 | J24: =SUM(H24:I24) -> 0 | K24: =SUM(G24,J24) -> 0
C25: 小計 | E25: =SUM(E21:E24) -> 2035 | F25: =SUM(F21:F24) -> 2035 | G25: =SUM(G21:G24) -> 4070 | H25: =SUM(H21:H24) -> 2035 | I25: =SUM(I21:I24) -> 2093 | J25: =SUM(J21:J24) -> 4128 | K25: =SUM(K21:K24) -> 8198
B26: サービス（自主ビなど）
G27: =SUM(E27:F27) -> 0 | J27: =SUM(H27:I27) -> 0 | K27: =SUM(G27,J27) -> 0
G28: =SUM(E28:F28) -> 0 | J28: =SUM(H28:I28) -> 0 | K28: =SUM(G28,J28) -> 0
G29: =SUM(E29:F29) -> 0 | J29: =SUM(H29:I29) -> 0 | K29: =SUM(G29,J29) -> 0
G30: =SUM(E30:F30) -> 0 | J30: =SUM(H30:I30) -> 0 | K30: =SUM(G30,J30) -> 0
C31: 小計 | E31: =SUM(E27:E30) -> 0 | F31: =SUM(F27:F30) -> 0 | G31: =SUM(G27:G30) -> 0 | H31: =SUM(H27:H30) -> 0 | I31: =SUM(I27:I30) -> 0 | J31: =SUM(J27:J30) -> 0 | K31: =SUM(K27:K30) -> 0
C32: 合計 | E32: =SUM(E13,E19,E25,E31) -> 17700 | F32: =SUM(F13,F19,F25,F31) -> 18400 | G32: =SUM(G13,G19,G25,G31) -> 36100 | H32: =SUM(H13,H19,H25,H31) -> 18400 | I32: =SUM(I13,I19,I25,I31) -> 19500 | J32: =SUM(J13,J19,J25,J31) -> 37900 | K32: =SUM(K13,K19,K25,K31) -> 74000
B34: 【要員計画】
C35: 要員数 | E35: 8 | F35: 8 | G35: =AVERAGE(E35:F35) -> 8 | H35: 8 | I35: 8 | J35: =AVERAGE(H35:I35) -> 8 | K35: =AVERAGE(G35,J35) -> 8
C36: 一人当たりの売上 | E36: =IF(E35<>0,E32/E35,0) -> 2212.5 | F36: =IF(F35<>0,F32/F35,0) -> 2300 | G36: =SUM(E36:F36) -> 4512.5 | H36: =IF(H35<>0,H32/H35,0) -> 2300 | I36: =IF(I35<>0,I32/I35,0) -> 2437.5 | J36: =SUM(H36:I36) -> 4737.5 | K36: =SUM(G36,J36) -> 9250
C37: 一人当たりの売上（月） | E37: =E36/3 -> 737.5 | F37: =F36/3 -> 766.66667 | G37: =G36/6 -> 752.08333 | H37: =H36/3 -> 766.66667 | I37: =I36/3 -> 812.5 | J37: =J36/6 -> 789.58333 | K37: =K36/12 -> 770.83333
B39: 2025年度売上見込み | D39: 72340
B41: 2025年度予算（110%） | D41: =D39*1.1 -> 79574
B42: 差額(年) | D42: =D39-D41 -> -7234 | E42: =D42/10*-1 -> 723.4 | F42: 万円
B43: 差額(月) | D43: =D42/12 -> -602.83333 | E43: =D43/10*-1 -> 60.283333 | F43: 万円
...

Sheet 区分
B2: 部門名 | C2: 受注区分 | D2: 商談区分
B3: 第一システムグループ | D3: 富士通
B4: 第二システムグループ | D4: 富士通関連
B5: アプリ開発グループ | D5: 自社顧客
B6: システム基盤グループ | D6: MS関連
D7: その他
D8: 努力目標
E14: =410000-409123 -> 877 | F14: =E14/4 -> 219.25
